Workbook

Sheet Emitem
A1: CÓDIGO | B1: CORRETORA | C1: E-mail | D1: Supervisor | E1: Data inclusão | F1: EMISSAO DE NF PREVISTA
A2: 153434 | B2: =VLOOKUP(A2,Base!$A:$D,2,0) -> BENVENUTO CORRETORA DE SEGUROS | C2: =VLOOKUP(A2,Base!A:D,3,0) -> financeiro@benvenutoseguros.com.br | D2: =VLOOKUP(B2,Base!B:E,3,0) -> MATHIAS SILVA | F2: Semanal
A3: 111061 | B3: =VLOOKUP(A3,Base!$A:$D,2,0) -> DGA CONSULT E CORRET DE SEG | C3: =VLOOKUP(A3,Base!A:D,3,0) -> daiane@dgacorretoradeseguros.com | D3: =VLOOKUP(B3,Base!B:E,3,0) -> BRUNA SANTANA | F3: Semanal
A4: 51943 | B4: =VLOOKUP(A4,Base!$A:$D,2,0) -> ENOVAX CORRETORA | C4: =VLOOKUP(A4,Base!A:D,3,0) -> diego.sargaco@enovax.com.br | D4: =VLOOKUP(B4,Base!B:E,3,0) -> BEIBIANA MARQUES | F4: Semanal
A5: 82094 | B5: =VLOOKUP(A5,Base!$A:$D,2,0) -> EPOS CORRETORA DE SEGUROS LTDA | C5: =VLOOKUP(A5,Base!A:D,3,0) -> comercial@eposcorretora.com.br | D5: =VLOOKUP(B5,Base!B:E,3,0) -> MATHIAS SILVA | F5: Semanal
A6: 62251 | B6: =VLOOKUP(A6,Base!$A:$D,2,0) -> HALEMBECK CORRETORA DE SEGUROS LTDA | C6: =VLOOKUP(A6,Base!A:D,3,0) -> suportesaude@halembeck.com | D6: =VLOOKUP(B6,Base!B:E,3,0) -> BEIBIANA MARQUES | F6: Semanal
A7: 135917 | B7: =VLOOKUP(A7,Base!$A:$D,2,0) -> ACNWB CORRETORA DE SEGUROS EIRELI | C7: =VLOOKUP(A7,Base!A:D,3,0) -> ACNWBSEGUROS@GMAIL.COM | D7: =VLOOKUP(B7,Base!B:E,3,0) -> MATHIAS SILVA | F7: Mensal
A8: 92371 | B8: =VLOOKUP(A8,Base!$A:$D,2,0) -> KARLA A DE A BASSI EPP | C8: =VLOOKUP(A8,Base!A:D,3,0) -> atendimento@ab6corretora.com.br | D8: =VLOOKUP(B8,Base!B:E,3,0) -> THAYNARA SANTOS | F8: Semanal
A9: 67570 | B9: =VLOOKUP(A9,Base!$A:$D,2,0) -> ADELIZ NUNES | C9: =VLOOKUP(A9,Base!A:D,3,0) -> adeliz.nunes@affinitycorretora.com.br | D9: =VLOOKUP(B9,Base!B:E,3,0) -> ALVARO VARELA | F9: Mensal
A10: 81069 | B10: =VLOOKUP(A10,Base!$A:$D,2,0) -> MOLISANI CONSORCIO E SEGUROS LTDA | C10: =VLOOKUP(A10,Base!A:D,3,0) -> willmolisani@gmail.com | D10: =VLOOKUP(B10,Base!B:E,3,0) -> THAYNARA SANTOS | F10: Semanal
A11: 104779 | B11: =VLOOKUP(A11,Base!$A:$D,2,0) -> ADRIANA CAMPOAMOR CORRET DE SEG LTDA EPP | C11: =VLOOKUP(A11,Base!A:D,3,0) -> adrianac-corretora@uol.com.br | D11: =VLOOKUP(B11,Base!B:E,3,0) -> MICHELE BERNARDO | F11: Mensal
A12: 157518 | B12: =VLOOKUP(A12,Base!$A:$D,2,0) -> PIRANI ADMINISTRADORA E CORRETORA DE SEGUROS LTDA | C12: =VLOOKUP(A12,Base!A:D,3,0) -> beneficios@pirani.com.br | D12: =VLOOKUP(B12,Base!B:E,3,0) -> MATHIAS SILVA | F12: Semanal
A13: 155466 | B13: =VLOOKUP(A13,Base!$A:$D,2,0) -> PLAVEN CORRETORA DE SEGUROS LTDA | C13: =VLOOKUP(A13,Base!A:D,3,0) -> plavencorretora@uol.com.br | D13: =VLOOKUP(B13,Base!B:E,3,0) -> MATHIAS SILVA | F13: Semanal
... A63: 201017 | B63: =VLOOKUP(A63,Base!$A:$D,2,0) -> REDUÇAO SAUDE CONSULTORIA DE BENEFICIOS EIRELI | C63: =VLOOKUP(A63,Base!A:D,3,0) -> fabio@reducaosaude.com.br | D63: =VLOOKUP(B63,Base!B:E,3,0) -> MICHELE BERNARDO | F63: Mensal
A64: 205859 | B64: =VLOOKUP(A64,Base!$A:$D,2,0) -> ERZ ADM e Corretora de Seguros | C64: =VLOOKUP(A64,Base!A:D,3,0) -> consultoria.digital@erzseg.com | D64: =VLOOKUP(B64,Base!B:E,3,0) -> GABRIELLY VARRICHIO | E64: 44939 | F64: Mensal
A65: 205206 | B65: =VLOOKUP(A65,Base!$A:$D,2,0) -> Fontes EF Corretora de Seguros LTDA | C65: =VLOOKUP(A65,Base!A:D,3,0) -> fontes@fontescorretora.com.br | D65: =VLOOKUP(B65,Base!B:E,3,0) -> AMANDA SOUZA | E65: 44900 | F65: Mensal
A66: 202659 | B66: =VLOOKUP(A66,Base!$A:$D,2,0) -> FORMA CORRETORA DE SEGUROS LTDA | C66: =VLOOKUP(A66,Base!A:D,3,0) -> claudia.silva@formaseguros.com.br | D66: =VLOOKUP(B66,Base!B:E,3,0) -> JESSICA GONZAGA | F66: Semanal
A67: 204865 | B67: =VLOOKUP(A67,Base!$A:$D,2,0) -> GABRIEL SOUZA | C67: =VLOOKUP(A67,Base!A:D,3,0) -> gabriel.souza@affinitycorretora.com.br | D67: =VLOOKUP(B67,Base!B:E,3,0) -> ALVARO VARELA | F67: Semanal
A68: 194750 | B68: =VLOOKUP(A68,Base!$A:$D,2,0) -> NBSEGUROS ADMINISTRACAO E CORRETAGEM DE SEGUROS S/S LTDA | C68: =VLOOKUP(A68,Base!A:D,3,0) -> fabia@novabartira.com.br | D68: =VLOOKUP(B68,Base!B:E,3,0) -> THAYNARA SANTOS | F68: Semanal
A69: 97536 | B69: =VLOOKUP(A69,Base!$A:$D,2,0) -> DECIDE CORRETORA DE SEGUROS & CONSULTORIA LTDA | C69: =VLOOKUP(A69,Base!A:D,3,0) -> decideseguros@decideseguros.com.br | D69: =VLOOKUP(B69,Base!B:E,3,0) -> THAYNARA SANTOS | F69: Semanal
A70: 203319 | B70: =VLOOKUP(A70,Base!$A:$D,2,0) -> LUK CONSULTORIA E CORRETORA DE SEGUROS EIRELI | C70: =VLOOKUP(A70,Base!A:D,3,0) -> luciane@lukconsultoria.com.br | D70: =VLOOKUP(B70,Base!B:E,3,0) -> MATHIAS SILVA | F70: Semanal
A71: 66396 | B71: =VLOOKUP(A71,Base!$A:$D,2,0) -> TCA ADMINISTRADORA E CORRETORA DE SEGUROS LTDA | C71: =VLOOKUP(A71,Base!A:D,3,0) -> bruno.beraldo@tcaseguros.com.br | D71: =VLOOKUP(B71,Base!B:E,3,0) -> THALITA MELO | F71: Semanal
A72: 119509 | B72: =VLOOKUP(A72,Base!$A:$D,2,0) -> GABRIELLY VARRICHIO | C72: =VLOOKUP(A72,Base!A:D,3,0) -> gabrielly.varrichio@affinitycorretora.com.br | D72: =VLOOKUP(B72,Base!B:E,3,0) -> ALVARO VARELA | E72: 44930 | F72: Mensal
A73: 89310 | B73: =VLOOKUP(A73,Base!$A:$D,2,0) -> GLOBAL API CORRETORA DE SEGUROS EIRELI | C73: =VLOOKUP(A73,Base!A:D,3,0) -> globalapicorretora@gmail.com | D73: =VLOOKUP(B73,Base!B:E,3,0) -> THAYNARA SANTOS | F73: Mensal
A74: 202636 | B74: =VLOOKUP(A74,Base!$A:$D,2,0) -> IN SOLUCOES EMPRESARIAIS E CORRETAGEM DE SEGUROS LTDA | C74: =VLOOKUP(A74,Base!A:D,3,0) -> operacional@solucoes.in | D74: =VLOOKUP(B74,Base!B:E,3,0) -> AMANDA SOUZA | F74: Semanal
A75: 202849 | B75: =VLOOKUP(A75,Base!$A:$D,2,0) -> SOLUTION FOR LIFE CORRETORA E ADMINISTRADORA DE SEGUROS LTDA | C75: =VLOOKUP(A75,Base!A:D,3,0) -> saude@solutionforlife.com.br | D75: =VLOOKUP(B75,Base!B:E,3,0) -> THALITA MELO | F75: Semanal
A76: 203810 | B76: =VLOOKUP(A76,Base!$A:$D,2,0) -> Via Mais Corretora de Seguros e Beneficios Ltda | C76: =VLOOKUP(A76,Base!A:D,3,0) -> solange.medeiros@viadiretanet.com.br | D76: =VLOOKUP(B76,Base!B:E,3,0) -> MARLI ANDRADE | E76: 44571 | F76: Semanal
A77: 66383 | B77: =VLOOKUP(A77,Base!$A:$D,2,0) -> OPEN HEALTH CORRETORA DE SEGUROS LTDA | C77: =VLOOKUP(A77,Base!A:D,3,0) -> iraja@openseg.com.br | D77: =VLOOKUP(B77,Base!B:E,3,0) -> BRUNA SANTANA | F77: Semanal
A78: 196917 | B78: =VLOOKUP(A78,Base!$A:$D,2,0) -> GOLDEN PROTECTION CORRETORA DE SEGUROS LTDA | C78: =VLOOKUP(A78,Base!A:D,3,0) -> fernandosouza@goldenprotectionseg.com.br | D78: =VLOOKUP(B78,Base!B:E,3,0) -> BEIBIANA MARQUES | F78: Mensal
A79: 183345 | B79: =VLOOKUP(A79,Base!$A:$D,2,0) -> Mappi Corretora de Seguros Ltda Me | C79: =VLOOKUP(A79,Base!A:D,3,0) -> mappiseguros@outlook.com | D79: =VLOOKUP(B79,Base!B:E,3,0) -> THALITA MELO | F79: Semanal
A80: 203729 | B80: =VLOOKUP(A80,Base!$A:$D,2,0) -> SVITEK CORRETORA DE SEGUROS | C80: =VLOOKUP(A80,Base!A:D,3,0) -> svitek@terra.com.br | D80: =VLOOKUP(B80,Base!B:E,3,0) -> THALITA MELO | F80: Semanal
A81: 98574 | B81: =VLOOKUP(A81,Base!$A:$D,2,0) -> FIDELE SEGUROS | C81: =VLOOKUP(A81,Base!A:D,3,0) -> implantacao@fideleseguros.com.br | D81: =VLOOKUP(B81,Base!B:E,3,0) -> GABRIELLY VARRICHIO | F81: Semanal
A82: 202670 | B82: =VLOOKUP(A82,Base!$A:$D,2,0) -> FMP CORRETORA DE SEGUROS LTDA ME | C82: =VLOOKUP(A82,Base!A:D,3,0) -> fabricio@fmpcorretora.com.br | D82: =VLOOKUP(B82,Base!B:E,3,0) -> VINICIUS ADDEU SUP | F82: Semanal
A83: 167960 | B83: =VLOOKUP(A83,Base!$A:$D,2,0) -> MATOS & MONTEIRO CORRETORA DE SEGURO DE VIDA LTDA | C83: =VLOOKUP(A83,Base!A:D,3,0) -> matosmonteiro@matosmonteiro.com.br | D83: =VLOOKUP(B83,Base!B:E,3,0) -> MATHIAS SILVA | F83: Semanal
A84: 203087 | B84: =VLOOKUP(A84,Base!$A:$D,2,0) -> DEBORA PEREIRA DE ANDRADE | C84: =VLOOKUP(A84,Base!A:D,3,0) -> debora@delianseg.com.br | D84: =VLOOKUP(B84,Base!B:E,3,0) -> BRUNA SANTANA | E84: 44609 | F84: Semanal
A85: 77966 | B85: =VLOOKUP(A85,Base!$A:$D,2,0) -> MORETO E GOUVEA CORRETORA DE SEGUROS LTDA -EPP | C85: =VLOOKUP(A85,Base!A:D,3,0) -> nathalia@moretoegouvea.com.br | D85: =VLOOKUP(B85,Base!B:E,3,0) -> THAYNARA SANTOS | E85: 44638 | F85: Semanal
A86: 202360 | B86: =VLOOKUP(A86,Base!$A:$D,2,0) -> BAUER CORRETORA DE SEGUROS LTDA | C86: =VLOOKUP(A86,Base!A:D,3,0) -> comercial@bauercorretora.com | D86: =VLOOKUP(B86,Base!B:E,3,0) -> MYLLENA FERNANDES | E86: 44648 | F86: Semanal
A87: 164878 | B87: =VLOOKUP(A87,Base!$A:$D,2,0) -> M. K. BRASIL ADMINISTRACAO E CORRETAGEM DE SEGUROS LTDA | C87: =VLOOKUP(A87,Base!A:D,3,0) -> COMERCIALSAUDE@MKBRASIL.COM | D87: =VLOOKUP(B87,Base!B:E,3,0) -> MATHIAS SILVA | E87: 44655 | F87: Semanal
A88: 190606 | B88: =VLOOKUP(A88,Base!$A:$D,2,0) -> KENDRA Corretora de Seguros Ltda | C88: =VLOOKUP(A88,Base!A:D,3,0) -> tatiana@kendraseguros.com.br | D88: =VLOOKUP(B88,Base!B:E,3,0) -> THALITA MELO | F88: Semanal
A89: 204013 | B89: =VLOOKUP(A89,Base!$A:$D,2,0) -> VIVER SEGURO - CONSULTORIA, ADMINISTRAÇÃO E CORRETAGEM DE SEGUROS | C89: =VLOOKUP(A89,Base!A:D,3,0) -> rubens@viversegurocorretora.com.br | D89: =VLOOKUP(B89,Base!B:E,3,0) -> BRUNA SANTANA | E89: 44662 | F89: Semanal
...

Sheet Base
A1: Código | B1: Nome | C1: Email | D1: Assistente
A2: 215876 | B2: ANDREA PAULA BARRETO NEJAIM MEIRA | C2: corretoraandreameira@gmail.com | D2: JAQUELINE SOARES
A3: 216906 | B3: IMPACTO CERTIFICAÇÕES E CORRETORA DE SEGUROS LTDA | C3: seguros2@impactoassessores.com.br | D3: JESSICA GONZAGA
A4: 208641 | B4: 11PONTO11 CORRETORA DE SEGUROS & PROTECAO LTDA | C4: saulo.guimaraes@11ponto11.com.br | D4: THALITA MELO
A5: 212605 | B5: 19.865.635 ELAINE CRISTINA DE OLIVEIRA COSTA SABINO | C5: prayersaudeconsultoria@gmail.com | D5: JACQUELINE BARBOZA
A6: 217041 | B6: 2 EM 1 CONSULTORIA EM BENEFICIOS | C6: 2em1consultoriarj@gmail.com | D6: CAROLINE VIVAS
A7: 211463 | B7: 22.281.415 MIRIAM DE PAULA DA SILVA | C7: miriamtedhels@gmail.com | D7: MICHELE OLIVEIRA
A8: 217247 | B8: 26.409.715 CAMILA VIEIRA DA SILVA | C8: camila.vieira@adhikariconsultoria.com.br | D8: THAYNARA SANTOS
A9: 214207 | B9: 26.983.424 VANESSA DE CASTRO GALEGO DIAS | C9: vanessa@galegosaude.com.br | D9: INGRID SOUZA
A10: 206281 | B10: 2R'S CORRETORA E ADM DE SEGUROS LTDA | C10: rita@2rsseguros.com.br | D10: THAYNARA SANTOS
A11: 216680 | B11: 30.607.650 FLAVIO VENTURA DE ANDRADE | C11: flaviooventura@gmail.com | D11: NATHALIA NARDELLI
A12: 207270 | B12: 33.720.035 VICTORIA ALVES GREGORIO MARQUES | C12: g.vsaopaulo@outlook.com | D12: THALITA MELO
A13: 201046 | B13: 34.980.893 RENATA MORAES NEVES RODRIGUES | C13: renata.nrodrigues@hotmail.com | D13: AMANDA SOUZA
... A22: 211535 | B22: 42.930.215 ANA PAULA BUSCHERMOHLE | C22: anabplanosdesaude@outlook.com | D22: CAROLINE VIVAS
A23: 211509 | B23: 43.199.169 PRISCYLA DE ANDRADE FERREIRA | D23: LAIS LIMA
A24: 217201 | B24: 43.956.997 RAPHAEL TAVARES DA SILVA MANHAES | C24: raphael.ts.manhaes@gmail.com | D24: NATHALIA NARDELLI
A25: 216866 | B25: 44.642.472 ALEXANDRE CHERFAN GOULART NOGUEIRA | C25: 1986.acgn@gmail.com | D25: DANIELA BARBOSA
A26: 214777 | B26: 45.714.980 ADRIANA SAMPAIO CUNHA DA COSTA | C26: adrianasampaiocorretora@gmail.com | D26: ANNA FREITAS
A27: 212463 | B27: 47.717.458 ALINE MARIA DO NASCIMENTO | C27: aline_amn@yahoo.com.br | D27: NATHALIA NARDELLI
A28: 206513 | B28: 49.162.551 YAN ZANELATO DA SILVA | C28: wayconsig@gmail.com | D28: NATHALIA NARDELLI
A29: 214254 | B29: 49.396.915 JOAO PAULO REATTI | C29: joaopauloreatti@gmail.com | D29: INGRID SOUZA
A30: 211575 | B30: 49.412.381 Tamara Ingrid dos Santos | C30: seguros.tamaraingrid@gmail.com | D30: JENNIFER OLIVEIRA
A31: 215798 | B31: 49.466.127 BRUNO ROBERTO DE LIMA BENTO | C31: bl.corretorr@gmail.com | D31: ANNA FREITAS
A32: 215013 | B32: 49337555 GABRIELA FRANZIN JULIAO DA SILVA | C32: gabrielafranzinjs@gmail.com | D32: MARLI ANDRADE
A33: 210837 | B33: 4HELP CORRETORA DE SEGUROS LTDA | C33: andre@4helpseguros.com.br | D33: BRUNA SANTANA
A34: 208616 | B34: 4YOU CORRETORA DE SEGUROS LTDA | C34: analu@4youcorretoradeseguros.com.br | D34: THALITA MELO
A35: 213478 | B35: 50.610.554 LUCAS NUNES ALVES | C35: lucasnunes@azakseguros.com.br | D35: THALITA MELO
... A37: 214979 | B37: 51.200.170 GABRIELA SAMPAIO CASTRO | C37: scastro.gabriela@gmail.com | D37: GABRIELLY VARRICHIO
A38: 211379 | B38: 51.468.632 MARIA EDUARDA DOS SANTOS MACHADO | D38: ANNA FREITAS
A39: 216941 | B39: 51.641.287 TAINA DA SILVA LIMA | C39: taina.lima@rzplanos.com.br | D39: MICHELE BERNARDO
A40: 215503 | B40: 52.665.074 ANDRESSA MORALES BATISTA ROCHA | C40: dessamnb@gmail.com | D40: JESSICA GONZAGA
A41: 216431 | B41: 53.335.627 ROSIANE CORDEIRO FARIAS | C41: rosiane.saude@hotmail.com | D41: DANIELA BARBOSA
A42: 216463 | B42: 53.626.759 MATHEUS MENDES MORAES | C42: sdrmatheusmendes@gmail.com | D42: INGRID SOUZA
A43: 111042 | B43: 53.992.708 ANDERSON JANDOSA CORDEIRO | C43: ajandosa.consultor@gmail.com | D43: JESSICA GONZAGA
A44: 214100 | B44: 55.064.723 ALEXANDRE JULIO CEDIRIAN | C44: acedirian@gmail.com | D44: MICHELE BERNARDO
A45: 214387 | B45: 55.071.073 RAFAEL OLIVEIRA DOS SANTOS GONÇALVES | C45: aaseguros.corretora@gmail.com | D45: MARLI ANDRADE
A46: 214085 | B46: 55.195.486 LUCAS NOBREGA DE OLIVEIRA | C46: nobregalucas911@gmail.com | D46: FLAVIO TEODORO
A47: 217235 | B47: 55.304.469 CLARICE ALVES SOUZA | C47: clarice.corretoradeseguros@gmail.com | D47: AMANDA PUZISKI
A48: 215765 | B48: 56.201.853 RAPHAEL ZIBINI LAMUCIO | C48: raphael@zibiniseguros.com.br | D48: GABRIELLY VARRICHIO
A49: 214982 | B49: 56.823.426 FRANCISCO MOINO FILHO | C49: redire19@gmail.com | D49: JESSICA GONZAGA
...
